<?xml version="1.0" encoding="utf-8"?>
<!-- This URDF was automatically created by SolidWorks to URDF Exporter! Originally created by Stephen Brawner (brawner@gmail.com) 
     Commit Version: 1.6.0-4-g7f85cfe  Build Version: 1.6.7995.38578
     For more information, please see http://wiki.ros.org/sw_urdf_exporter -->
<robot
  name="TestStation_Draft_set0">
  <link
    name="base">
    <inertial>
      <origin
        xyz="-0.140609630307133 0.140146936008361 0.359999999999999"
        rpy="0 0 0" />
      <mass
        value="1.36955126412918" />
      <inertia
        ixx="0.0486076021163975"
        ixy="1.7149227845229E-19"
        ixz="1.82022317531097E-16"
        iyy="0.0491079736049732"
        iyz="2.37949729684336E-17"
        izz="0.00117016823735803" />
    </inertial>
    <visual>
      <origin
        xyz="0 0 0"
        rpy="0 0 0" />
      <geometry>
        <mesh
          filename="package://TestStation_Draft_set0/meshes/base.STL" />
      </geometry>
      <material
        name="">
        <color
          rgba="0.666666666666667 0.698039215686274 0.768627450980392 1" />
      </material>
    </visual>
    <collision>
      <origin
        xyz="0 0 0"
        rpy="0 0 0" />
      <geometry>
        <mesh
          filename="package://TestStation_Draft_set0/meshes/base.STL" />
      </geometry>
    </collision>
  </link>
  <link
    name="linear_left_right">
    <inertial>
      <origin
        xyz="-0.00473553417931471 -0.0625353696963205 0.00514181443208439"
        rpy="0 0 0" />
      <mass
        value="0.50020845309243" />
      <inertia
        ixx="0.00169572123741561"
        ixy="1.54614743410363E-08"
        ixz="-1.68555320135368E-10"
        iyy="0.000137994764046023"
        iyz="-1.97213666431506E-07"
        izz="0.00156459105637991" />
    </inertial>
    <visual>
      <origin
        xyz="0 0 0"
        rpy="0 0 0" />
      <geometry>
        <mesh
          filename="package://TestStation_Draft_set0/meshes/linear_left_right.STL" />
      </geometry>
      <material
        name="">
        <color
          rgba="0.647058823529412 0.619607843137255 0.588235294117647 1" />
      </material>
    </visual>
    <collision>
      <origin
        xyz="0 0 0"
        rpy="0 0 0" />
      <geometry>
        <mesh
          filename="package://TestStation_Draft_set0/meshes/linear_left_right.STL" />
      </geometry>
    </collision>
  </link>
  <joint
    name="linear_left_right_joint"
    type="prismatic">
    <origin
      xyz="-0.132 0.217 0.0475"
      rpy="0 0 0" />
    <parent
      link="base" />
    <child
      link="linear_left_right" />
    <axis
      xyz="0 0 1" />
    <limit
      lower="0"
      upper="0"
      effort="0"
      velocity="0" />
  </joint>
  <link
    name="linear_up_down">
    <inertial>
      <origin
        xyz="-0.00439209640008409 -0.0187193775729318 2.03306522772451E-05"
        rpy="0 0 0" />
      <mass
        value="0.0486613560338948" />
      <inertia
        ixx="3.87990604135854E-05"
        ixy="1.12807309653712E-06"
        ixz="-2.1218999231562E-21"
        iyy="3.63288422216328E-05"
        iyz="-1.18052355540521E-20"
        izz="2.87573906928628E-05" />
    </inertial>
    <visual>
      <origin
        xyz="0 0 0"
        rpy="0 0 0" />
      <geometry>
        <mesh
          filename="package://TestStation_Draft_set0/meshes/linear_up_down.STL" />
      </geometry>
      <material
        name="">
        <color
          rgba="0.647058823529412 0.619607843137255 0.588235294117647 1" />
      </material>
    </visual>
    <collision>
      <origin
        xyz="0 0 0"
        rpy="0 0 0" />
      <geometry>
        <mesh
          filename="package://TestStation_Draft_set0/meshes/linear_up_down.STL" />
      </geometry>
    </collision>
  </link>
  <joint
    name="linear_up_down_joint"
    type="prismatic">
    <origin
      xyz="0.01652 -0.12255 0.00496"
      rpy="1.5708 -1.5708 0" />
    <parent
      link="linear_left_right" />
    <child
      link="linear_up_down" />
    <axis
      xyz="0 0 1" />
    <limit
      lower="-0.095"
      upper="0"
      effort="0"
      velocity="0" />
  </joint>
  <link
    name="hip">
    <inertial>
      <origin
        xyz="0.0386776398609989 -0.00250196399820506 -0.000178777924488061"
        rpy="0 0 0" />
      <mass
        value="0.112927711686256" />
      <inertia
        ixx="9.63204924063097E-05"
        ixy="8.25781035279412E-06"
        ixz="2.7304014401897E-06"
        iyy="0.000126871341522832"
        iyz="-1.81540597478815E-07"
        izz="0.00012677953494202" />
    </inertial>
    <visual>
      <origin
        xyz="0 0 0"
        rpy="0 0 0" />
      <geometry>
        <mesh
          filename="package://TestStation_Draft_set0/meshes/hip.STL" />
      </geometry>
      <material
        name="">
        <color
          rgba="0.650980392156863 0.619607843137255 0.588235294117647 1" />
      </material>
    </visual>
    <collision>
      <origin
        xyz="0 0 0"
        rpy="0 0 0" />
      <geometry>
        <mesh
          filename="package://TestStation_Draft_set0/meshes/hip.STL" />
      </geometry>
    </collision>
  </link>
  <joint
    name="hip_joint"
    type="revolute">
    <origin
      xyz="0 -0.04148 0.0005"
      rpy="3.1416 0 0" />
    <parent
      link="linear_up_down" />
    <child
      link="hip" />
    <axis
      xyz="0 0 1" />
    <limit
      lower="0"
      upper="0"
      effort="0"
      velocity="0" />
  </joint>
  <link
    name="knee">
    <inertial>
      <origin
        xyz="-0.0641230427387015 -0.033789944845913 0.00744656930615061"
        rpy="0 0 0" />
      <mass
        value="0.156494206633367" />
      <inertia
        ixx="0.000104384684543732"
        ixy="-8.17463676508195E-05"
        ixz="9.44237073334744E-11"
        iyy="0.000159994868773522"
        iyz="-9.22180171421696E-11"
        izz="0.000225522753728284" />
    </inertial>
    <visual>
      <origin
        xyz="0 0 0"
        rpy="0 0 0" />
      <geometry>
        <mesh
          filename="package://TestStation_Draft_set0/meshes/knee.STL" />
      </geometry>
      <material
        name="">
        <color
          rgba="0.650980392156863 0.619607843137255 0.588235294117647 1" />
      </material>
    </visual>
    <collision>
      <origin
        xyz="0 0 0"
        rpy="0 0 0" />
      <geometry>
        <mesh
          filename="package://TestStation_Draft_set0/meshes/knee.STL" />
      </geometry>
    </collision>
  </link>
  <joint
    name="knee_joint"
    type="revolute">
    <origin
      xyz="0.17558 0 0.071341"
      rpy="1.5708 0 0" />
    <parent
      link="hip" />
    <child
      link="knee" />
    <axis
      xyz="0 0 1" />
    <limit
      lower="0"
      upper="0"
      effort="0"
      velocity="0" />
  </joint>
  <link
    name="ankle">
    <inertial>
      <origin
        xyz="0.101955850878447 -0.00415979503152464 0.000484986222156494"
        rpy="0 0 0" />
      <mass
        value="0.345259086385849" />
      <inertia
        ixx="0.000202382465701839"
        ixy="9.72759216225016E-06"
        ixz="6.45255472789211E-07"
        iyy="0.000118668974296294"
        iyz="-3.14379577232909E-06"
        izz="0.000180984165274749" />
    </inertial>
    <visual>
      <origin
        xyz="0 0 0"
        rpy="0 0 0" />
      <geometry>
        <mesh
          filename="package://TestStation_Draft_set0/meshes/ankle.STL" />
      </geometry>
      <material
        name="">
        <color
          rgba="0.650980392156863 0.619607843137255 0.588235294117647 1" />
      </material>
    </visual>
    <collision>
      <origin
        xyz="0 0 0"
        rpy="0 0 0" />
      <geometry>
        <mesh
          filename="package://TestStation_Draft_set0/meshes/ankle.STL" />
      </geometry>
    </collision>
  </link>
  <joint
    name="ankle_joint"
    type="revolute">
    <origin
      xyz="-0.097579 -0.06984 0"
      rpy="0 0 0" />
    <parent
      link="knee" />
    <child
      link="ankle" />
    <axis
      xyz="0 0 1" />
    <limit
      lower="0"
      upper="0"
      effort="0"
      velocity="0" />
  </joint>
  <link
    name="end_effector">
    <inertial>
      <origin
        xyz="1.25016501595354E-08 0.00469008205891722 2.46554281713163E-08"
        rpy="0 0 0" />
      <mass
        value="0.00616673834560594" />
      <inertia
        ixx="4.10445260534004E-07"
        ixy="-7.57023254373874E-13"
        ixz="9.09931151049619E-13"
        iyy="3.10367283952649E-07"
        iyz="-1.63648124474137E-12"
        izz="4.06602144316907E-07" />
    </inertial>
    <visual>
      <origin
        xyz="0 0 0"
        rpy="0 0 0" />
      <geometry>
        <mesh
          filename="package://TestStation_Draft_set0/meshes/end_effector.STL" />
      </geometry>
      <material
        name="">
        <color
          rgba="0.501960784313725 0.501960784313725 0.501960784313725 1" />
      </material>
    </visual>
    <collision>
      <origin
        xyz="0 0 0"
        rpy="0 0 0" />
      <geometry>
        <mesh
          filename="package://TestStation_Draft_set0/meshes/end_effector.STL" />
      </geometry>
    </collision>
  </link>
  <joint
    name="end_effector"
    type="fixed">
    <origin
      xyz="0.097579 -0.11255 0"
      rpy="0 0 0" />
    <parent
      link="ankle" />
    <child
      link="end_effector" />
    <axis
      xyz="0 0 0" />
  </joint>
  <link
    name="contract_point">
    <inertial>
      <origin
        xyz="1.25016501595354E-08 0.0123015071741014 2.46553524957394E-08"
        rpy="0 0 0" />
      <mass
        value="0.00616673834560597" />
      <inertia
        ixx="4.1044526053422E-07"
        ixy="-7.57023245674931E-13"
        ixz="9.09931155420557E-13"
        iyy="3.10367283952962E-07"
        iyz="-1.6364812399062E-12"
        izz="4.0660214431713E-07" />
    </inertial>
    <visual>
      <origin
        xyz="0 0 0"
        rpy="0 0 0" />
      <geometry>
        <mesh
          filename="package://TestStation_Draft_set0/meshes/contract_point.STL" />
      </geometry>
      <material
        name="">
        <color
          rgba="0.501960784313725 0.501960784313725 0.501960784313725 1" />
      </material>
    </visual>
    <collision>
      <origin
        xyz="0 0 0"
        rpy="0 0 0" />
      <geometry>
        <mesh
          filename="package://TestStation_Draft_set0/meshes/contract_point.STL" />
      </geometry>
    </collision>
  </link>
  <joint
    name="contract_point"
    type="fixed">
    <origin
      xyz="0 -0.0076114 0"
      rpy="0 0 0" />
    <parent
      link="end_effector" />
    <child
      link="contract_point" />
    <axis
      xyz="0 0 0" />
  </joint>
</robot>